Workbook

Sheet Theory
K1: PT1 | L1: PT2
A2: PT, IP and Int Marks | J2: No.of.Candidates Registered | K2: =COUNTA($A$6:$A$546) -> 66 | L2: =COUNTA($A$6:$A$546) -> 66
A3: Course Code - Name | C3: 22EE401 & POWER GENERATION, TRANSMISSION AND DISTRIBUTION | J3: No.of.Candidates Appeared for the Exam | K3: =(K2- COUNTIF(D6:D389,"=AB")) -> 66 | L3: =(L2- COUNTIF(E6:E389,"=AB")) -> 66
A4: Faculty ID - Name | C4: Dr.SIVARAMAN P / EE1329 | J4: No.of.Candidates Absent for the Exam | K4: =K2-K3 -> 0 | L4: =L2-L3 -> 0
A5: S. No. | B5: Reg. No. | C5: Name | D5: PT1 (50) | E5: PT2 (50) | F5: Optional Test (50) | G5: IP (16) | H5: IM (40) | J5: No. of Candidates Passed the Exam | K5: =COUNTIF(D6:D546,">=25") -> 55 | L5: =COUNTIF(E6:E546,">=25") -> 53
A6: 1 | B6: 7376231EE102 | C6: ABINISHA S | D6: 33 | E6: 35 | G6: 15 | H6: 35 | J6: pass % | K6: =ROUND(K5/K2*100,2) -> 83.33 | L6: =ROUND(L5/L2*100,2) -> 80.3 | AF6: =IF(D6<>"",IF(D6="A",0,D6),"") -> 33 | AG6: =IF(E6<>"",IF(E6="A",0,E6),"") -> 35 | AH6: =IF(F6<>"",IF(F6="A",0,F6),"") | AJ6: =IF(G6<>"",IF(G6="A",0,G6),"") -> 15
A7: 2 | B7: 7376231EE103 | C7: ANANTHIKA A | D7: 33 | E7: 34 | G7: 15 | H7: 35 | J7: 0-20 | K7: =COUNTIFS(D6:D546,">=0",D6:D546,"<=10") -> 0 | L7: =COUNTIFS(E6:E546,">=0",E6:E546,"<=10") -> 1 | AF7: =IF(D7<>"",IF(D7="A",0,D7),"") -> 33 | AG7: =IF(E7<>"",IF(E7="A",0,E7),"") -> 34 | AH7: =IF(F7<>"",IF(F7="A",0,F7),"") | AJ7: =IF(G7<>"",IF(G7="A",0,G7),"") -> 15
A8: 3 | B8: 7376231EE104 | C8: ANBARASU G | D8: 18 | E8: 23 | G8: 9 | H8: 20 | J8: 21-50 | K8: =COUNTIFS(D6:D546,">10",D6:D546,"<=25") -> 12 | L8: =COUNTIFS(E6:E546,">10",E6:E546,"<=25") -> 12 | AF8: =IF(D8<>"",IF(D8="A",0,D8),"") -> 18 | AG8: =IF(E8<>"",IF(E8="A",0,E8),"") -> 23 | AH8: =IF(F8<>"",IF(F8="A",0,F8),"") | AJ8: =IF(G8<>"",IF(G8="A",0,G8),"") -> 9
A9: 4 | B9: 7376231EE105 | C9: ANUJA N | D9: 34 | E9: 33 | G9: 15 | H9: 35 | J9: 51-80 | K9: =COUNTIFS(D6:D546,">25",D6:D546,"<=40") -> 54 | L9: =COUNTIFS(E6:E546,">25",E6:E546,"<=40") -> 53 | AF9: =IF(D9<>"",IF(D9="A",0,D9),"") -> 34 | AG9: =IF(E9<>"",IF(E9="A",0,E9),"") -> 33 | AH9: =IF(F9<>"",IF(F9="A",0,F9),"") | AJ9: =IF(G9<>"",IF(G9="A",0,G9),"") -> 15
A10: 5 | B10: 7376231EE106 | C10: ARUN BHAGAVATH S | D10: 32 | E10: 32 | G10: 14 | H10: 32 | J10: 81-100 | K10: =COUNTIFS(D6:D546,">40",D6:D546,"<=50") -> 0 | L10: =COUNTIFS(E6:E546,">40",E6:E546,"<=50") -> 0 | AF10: =IF(D10<>"",IF(D10="A",0,D10),"") -> 32 | AG10: =IF(E10<>"",IF(E10="A",0,E10),"") -> 32 | AH10: =IF(F10<>"",IF(F10="A",0,F10),"") | AJ10: =IF(G10<>"",IF(G10="A",0,G10),"") -> 14
A11: 6 | B11: 7376231EE107 | C11: ARUNIKA T K | D11: 34 | E11: 34 | G11: 16 | H11: 35 | J11: CO Target | K11: ='Final Attainment'!E7 -> 58 | AF11: =IF(D11<>"",IF(D11="A",0,D11),"") -> 34 | AG11: =IF(E11<>"",IF(E11="A",0,E11),"") -> 34 | AH11: =IF(F11<>"",IF(F11="A",0,F11),"") | AJ11: =IF(G11<>"",IF(G11="A",0,G11),"") -> 16
A12: 7 | B12: 7376231EE108 | C12: BALAJI M J | D12: 34 | E12: 32 | G12: 16 | H12: 35 | J12: PT1 Attainment | K12: ='Final Attainment'!M21 -> 2 | L12: ='Final Attainment'!N21 -> 2 | M12: ='Final Attainment'!O21 -> 3 | AF12: =IF(D12<>"",IF(D12="A",0,D12),"") -> 34 | AG12: =IF(E12<>"",IF(E12="A",0,E12),"") -> 32 | AH12: =IF(F12<>"",IF(F12="A",0,F12),"") | AJ12: =IF(G12<>"",IF(G12="A",0,G12),"") -> 16
A13: 8 | B13: 7376231EE109 | C13: BHARANIDHARAN S | D13: 33 | E13: 32 | G13: 15 | H13: 34 | J13: PT2 Attainment | M13: ='Final Attainment'!O22 -> 3 | N13: ='Final Attainment'!P22 -> 2 | O13: ='Final Attainment'!Q22 -> 2 | AF13: =IF(D13<>"",IF(D13="A",0,D13),"") -> 33 | AG13: =IF(E13<>"",IF(E13="A",0,E13),"") -> 32 | AH13: =IF(F13<>"",IF(F13="A",0,F13),"") | AJ13: =IF(G13<>"",IF(G13="A",0,G13),"") -> 15
A14: 9 | B14: 7376231EE110 | C14: DEEPTHI A | D14: 36 | E14: 37 | G14: 16 | H14: 37 | J14: SEE Attainment | K14: ='Final Attainment'!M29 -> 3 | L14: ='Final Attainment'!N29 -> 2 | M14: ='Final Attainment'!O29 -> 3 | N14: ='Final Attainment'!P29 -> 0 | O14: ='Final Attainment'!Q29 -> 3 | AF14: =IF(D14<>"",IF(D14="A",0,D14),"") -> 36 | AG14: =IF(E14<>"",IF(E14="A",0,E14),"") -> 37 | AH14: =IF(F14<>"",IF(F14="A",0,F14),"") | AJ14: =IF(G14<>"",IF(G14="A",0,G14),"") -> 16
A15: 10 | B15: 7376231EE111 | C15: DEPEN T | D15: 14 | E15: 12 | G15: 3 | H15: 10 | AF15: =IF(D15<>"",IF(D15="A",0,D15),"") -> 14 | AG15: =IF(E15<>"",IF(E15="A",0,E15),"") -> 12 | AH15: =IF(F15<>"",IF(F15="A",0,F15),"") | AJ15: =IF(G15<>"",IF(G15="A",0,G15),"") -> 3
A16: 11 | B16: 7376231EE112 | C16: DHANUSHA CHITRA PALANISAMY | D16: 32 | E16: 28 | G16: 13 | H16: 30 | AF16: =IF(D16<>"",IF(D16="A",0,D16),"") -> 32 | AG16: =IF(E16<>"",IF(E16="A",0,E16),"") -> 28 | AH16: =IF(F16<>"",IF(F16="A",0,F16),"") | AJ16: =IF(G16<>"",IF(G16="A",0,G16),"") -> 13
A17: 12 | B17: 7376231EE113 | C17: DHARSHINI M | D17: 30 | E17: 34 | G17: 15 | H17: 34 | J17: PO1 | K17: ='Final Attainment'!F52 -> 2.3392 | AF17: =IF(D17<>"",IF(D17="A",0,D17),"") -> 30 | AG17: =IF(E17<>"",IF(E17="A",0,E17),"") -> 34 | AH17: =IF(F17<>"",IF(F17="A",0,F17),"") | AJ17: =IF(G17<>"",IF(G17="A",0,G17),"") -> 15
A18: 13 | B18: 7376231EE114 | C18: DHILIP M V | D18: 30 | E18: 22 | G18: 11 | H18: 26 | J18: PO2 | K18: ='Final Attainment'!G52 -> 2.3626667 | AF18: =IF(D18<>"",IF(D18="A",0,D18),"") -> 30 | AG18: =IF(E18<>"",IF(E18="A",0,E18),"") -> 22 | AH18: =IF(F18<>"",IF(F18="A",0,F18),"") | AJ18: =IF(G18<>"",IF(G18="A",0,G18),"") -> 11
A19: 14 | B19: 7376231EE115 | C19: DHIVA R | D19: 20 | E19: 10 | G19: 9 | H19: 17 | J19: PO3 | K19: ='Final Attainment'!H52 -> 2.3323077 | AF19: =IF(D19<>"",IF(D19="A",0,D19),"") -> 20 | AG19: =IF(E19<>"",IF(E19="A",0,E19),"") -> 10 | AH19: =IF(F19<>"",IF(F19="A",0,F19),"") | AJ19: =IF(G19<>"",IF(G19="A",0,G19),"") -> 9
A20: 15 | B20: 7376231EE116 | C20: GOWTHAM M | D20: 28 | E20: 24 | G20: 12 | H20: 27 | J20: PO4 | K20: ='Final Attainment'!I52 -> 2.2509091 | AF20: =IF(D20<>"",IF(D20="A",0,D20),"") -> 28 | AG20: =IF(E20<>"",IF(E20="A",0,E20),"") -> 24 | AH20: =IF(F20<>"",IF(F20="A",0,F20),"") | AJ20: =IF(G20<>"",IF(G20="A",0,G20),"") -> 12
A21: 16 | B21: 7376231EE117 | C21: GOWTHAM T | D21: 22 | E21: 33 | G21: 15 | H21: 31 | J21: PO5 | K21: ='Final Attainment'!J52 -> 1.368 | AF21: =IF(D21<>"",IF(D21="A",0,D21),"") -> 22 | AG21: =IF(E21<>"",IF(E21="A",0,E21),"") -> 33 | AH21: =IF(F21<>"",IF(F21="A",0,F21),"") | AJ21: =IF(G21<>"",IF(G21="A",0,G21),"") -> 15
A22: 17 | B22: 7376231EE118 | C22: HARIKRISHNA N | D22: 30 | E22: 31 | G22: 14 | H22: 32 | J22: PO6 | K22: ='Final Attainment'!K52 | AF22: =IF(D22<>"",IF(D22="A",0,D22),"") -> 30 | AG22: =IF(E22<>"",IF(E22="A",0,E22),"") -> 31 | AH22: =IF(F22<>"",IF(F22="A",0,F22),"") | AJ22: =IF(G22<>"",IF(G22="A",0,G22),"") -> 14
A23: 18 | B23: 7376231EE119 | C23: HARINI K S | D23: 31 | E23: 31 | G23: 14 | H23: 32 | J23: PO7 | K23: ='Final Attainment'!L52 | AF23: =IF(D23<>"",IF(D23="A",0,D23),"") -> 31 | AG23: =IF(E23<>"",IF(E23="A",0,E23),"") -> 31 | AH23: =IF(F23<>"",IF(F23="A",0,F23),"") | AJ23: =IF(G23<>"",IF(G23="A",0,G23),"") -> 14
A24: 19 | B24: 7376231EE120 | C24: JANANI N | D24: 33 | E24: 32 | G24: 15 | H24: 34 | J24: PO8 | K24: ='Final Attainment'!M52 | AF24: =IF(D24<>"",IF(D24="A",0,D24),"") -> 33 | AG24: =IF(E24<>"",IF(E24="A",0,E24),"") -> 32 | AH24: =IF(F24<>"",IF(F24="A",0,F24),"") | AJ24: =IF(G24<>"",IF(G24="A",0,G24),"") -> 15
A25: 20 | B25: 7376231EE121 | C25: JEBASTIN JOSEPH PAUL J | D25: 33 | E25: 36 | G25: 16 | H25: 36 | J25: PO9 | K25: ='Final Attainment'!N52 | AF25: =IF(D25<>"",IF(D25="A",0,D25),"") -> 33 | AG25: =IF(E25<>"",IF(E25="A",0,E25),"") -> 36 | AH25: =IF(F25<>"",IF(F25="A",0,F25),"") | AJ25: =IF(G25<>"",IF(G25="A",0,G25),"") -> 16
A26: 21 | B26: 7376231EE122 | C26: JEEVITHA S | D26: 35 | E26: 36 | G26: 16 | H26: 37 | J26: PO10 | K26: ='Final Attainment'!O52 -> 2.328 | AF26: =IF(D26<>"",IF(D26="A",0,D26),"") -> 35 | AG26: =IF(E26<>"",IF(E26="A",0,E26),"") -> 36 | AH26: =IF(F26<>"",IF(F26="A",0,F26),"") | AJ26: =IF(G26<>"",IF(G26="A",0,G26),"") -> 16
A27: 22 | B27: 7376231EE123 | C27: KAMALESH A P | D27: 33 | E27: 34 | G27: 16 | H27: 35 | J27: PO11 | K27: ='Final Attainment'!P52 | AF27: =IF(D27<>"",IF(D27="A",0,D27),"") -> 33 | AG27: =IF(E27<>"",IF(E27="A",0,E27),"") -> 34 | AH27: =IF(F27<>"",IF(F27="A",0,F27),"") | AJ27: =IF(G27<>"",IF(G27="A",0,G27),"") -> 16
A28: 23 | B28: 7376231EE124 | C28: KAMALESH VARMA V G | D28: 31 | E28: 29 | G28: 14 | H28: 32 | J28: PO12 | K28: ='Final Attainment'!Q52 | AF28: =IF(D28<>"",IF(D28="A",0,D28),"") -> 31 | AG28: =IF(E28<>"",IF(E28="A",0,E28),"") -> 29 | AH28: =IF(F28<>"",IF(F28="A",0,F28),"") | AJ28: =IF(G28<>"",IF(G28="A",0,G28),"") -> 14
A29: 24 | B29: 7376231EE125 | C29: KATHIR NITHESH R | D29: 32 | E29: 35 | G29: 15 | H29: 34 | J29: PSO1 | K29: ='Final Attainment'!R52 -> 2.3392 | AF29: =IF(D29<>"",IF(D29="A",0,D29),"") -> 32 | AG29: =IF(E29<>"",IF(E29="A",0,E29),"") -> 35 | AH29: =IF(F29<>"",IF(F29="A",0,F29),"") | AJ29: =IF(G29<>"",IF(G29="A",0,G29),"") -> 15
A30: 25 | B30: 7376231EE126 | C30: KAVITHA M | D30: 34 | E30: 34 | G30: 15 | H30: 35 | J30: PSO2 | K30: ='Final Attainment'!S52 -> 2.3323077 | AF30: =IF(D30<>"",IF(D30="A",0,D30),"") -> 34 | AG30: =IF(E30<>"",IF(E30="A",0,E30),"") -> 34 | AH30: =IF(F30<>"",IF(F30="A",0,F30),"") | AJ30: =IF(G30<>"",IF(G30="A",0,G30),"") -> 15
A31: 26 | B31: 7376231EE127 | C31: KAVIYARASU V K | D31: 29 | E31: 33 | G31: 14 | H31: 32 | J31: PSO3 | K31: ='Final Attainment'!T52 | AF31: =IF(D31<>"",IF(D31="A",0,D31),"") -> 29 | AG31: =IF(E31<>"",IF(E31="A",0,E31),"") -> 33 | AH31: =IF(F31<>"",IF(F31="A",0,F31),"") | AJ31: =IF(G31<>"",IF(G31="A",0,G31),"") -> 14
A32: 27 | B32: 7376231EE128 | C32: KEERTHISANKAR S | D32: 20 | E32: 31 | G32: 10 | H32: 25
A33: 28 | B33: 7376231EE129 | C33: KEERTHIVASAN S | D33: 29 | E33: 34 | G33: 14 | H33: 32
A34: 29 | B34: 7376231EE130 | C34: KHAJA PARVEZ T | D34: 31 | E34: 33 | G34: 14 | H34: 33
A35: 30 | B35: 7376231EE131 | C35: KIRUBA O C | D35: 19 | E35: 32 | G35: 14 | H35: 29 | K35: PT1 | L35: PT2
A36: 31 | B36: 7376231EE132 | C36: KOWSHIK ARAVIND K S P | D36: 34 | E36: 34 | G36: 16 | H36: 36 | J36: Min | K36: =MIN(D6:D197) -> 14 | L36: =MIN(E6:E197) -> 10
A37: 32 | B37: 7376231EE133 | C37: MANEESH D | D37: 28 | E37: 28 | G37: 12 | H37: 28 | J37: Max | K37: =MAX(D6:D197) -> 36 | L37: =MAX(E6:E197) -> 37
A38: 33 | B38: 7376231EE134 | C38: MATHIYARASI K | D38: 30 | E38: 33 | G38: 15 | H38: 33 | J38: Avg | K38: =AVERAGE(D6:D197) -> 29.333333 | L38: =AVERAGE(E6:E197) -> 29.424242
A39: 34 | B39: 7376231EE135 | C39: MAURYA A S | D39: 32 | E39: 33 | G39: 16 | H39: 34
A40: 35 | B40: 7376231EE136 | C40: MITHUN P P | D40: 33 | E40: 31 | G40: 15 | H40: 34 | J40: min out of 100 | K40: =K36*2 -> 28 | L40: =L36*2 -> 20
...

Sheet Graph
C3: No.of.Candidates Registered | D3: No.of.Candidates Appeared for the Exam | E3: No.of.Candidates Absent for the Exam | F3: No.of.Candidates Passed in the Exam | G3: PASS% | H3: Number of students scoring marks in the range mentioned | L3: Min | M3: Max | N3: Avg | O3: CO target | P3: CO1 attainment | Q3: CO2 attainment | R3: CO3 attainment | S3: CO4 attainment | T3: CO5 attainment
H4: 0-20 | I4: 21-50 | J4: 51-80 | K4: 81-100
B5: PT1 | C5: =Theory!K2 -> 66 | D5: =Theory!K3 -> 66 | E5: =Theory!K4 -> 0 | F5: =Theory!K5 -> 55 | G5: =Theory!K6 -> 83.33 | H5: =Theory!K7 -> 0 | I5: =Theory!K8 -> 12 | J5: =Theory!K9 -> 54 | K5: =Theory!K10 -> 0 | L5: =Theory!K40 -> 28 | M5: =Theory!K41 -> 72 | N5: =Theory!K42 -> 58.666667 | O5: =Theory!K11 -> 58 | P5: =Theory!K12 -> 2 | Q5: =Theory!L12 -> 2 | R5: =Theory!M12 -> 3
B6: PT2 | C6: =Theory!L2 -> 66 | D6: =Theory!L3 -> 66 | E6: =Theory!L4 -> 0 | F6: =Theory!L5 -> 53 | G6: =Theory!L6 -> 80.3 | H6: =Theory!L7 -> 1 | I6: =Theory!L8 -> 12 | J6: =Theory!L9 -> 53 | K6: =Theory!L10 -> 0 | L6: =Theory!L40 -> 20 | M6: =Theory!L41 -> 74 | N6: =Theory!L42 -> 58.848485 | O6: =Theory!K11 -> 58 | R6: =Theory!M13 -> 3 | S6: =Theory!N13 -> 2 | T6: =Theory!O13 -> 2
A12: =Theory!A3 -> Course Code - Name | B12: =Theory!C3 -> 22EE401 & POWER GENERATION, TRANSMISSION AND DISTRIBUTION
B13: PT1 ANALYSIS
B15: No. of students Appeared, Absent, Passed graph (Clustered Column Graph)
I16: Appeared | J16: Absent | K16: Passed
I17: =D5 -> 66 | J17: =E5 -> 0 | K17: =F5 -> 55
C31: Number of students in mark range (0-20. 21-50. 51-80. 81-100) graph (Clustered Column Graph) in % | I31: Percentage
I32: 0-20 | J32: 21-50 | K32: 51-80 | L32: 81-100
I33: =ROUND(H5/$D$5*100,2) -> 0 | J33: =ROUND(I5/$D$5*100,2) -> 18.18 | K33: =ROUND(J5/$D$5*100,2) -> 81.82 | L33: =ROUND(K5/$D$5*100,2) -> 0
C49: Min, Max and Avg., Mark comparison (Clustered Column Graph)
I50: Min | J50: Max | K50: Avg
I51: =L5 -> 28 | J51: =M5 -> 72 | K51: =N5 -> 58.666667
A68: =Theory!A3 -> Course Code - Name | B68: =Theory!C3 -> 22EE401 & POWER GENERATION, TRANSMISSION AND DISTRIBUTION
B69: PT2 ANALYSIS
B71: No. of students Appeared, Absent, Passed graph (Clustered Column Graph) | I71: Appeared | J71: Absent | K71: Passed
I72: =D6 -> 66 | J72: =E6 -> 0 | K72: =F6 -> 53
I82: 0-20 | J82: 21-50 | K82: 51-80 | L82: 81-100
I83: =ROUND(H6/$D$6*100,2) -> 1.52 | J83: =ROUND(I6/$D$6*100,2) -> 18.18 | K83: =ROUND(J6/$D$6*100,2) -> 80.3 | L83: =ROUND(K6/$D$6*100,2) -> 0
B88: Number of students in mark range (0-20. 21-50. 51-80. 81-100) graph (Clustered Column Graph) in %
I93: Min | J93: Max | K93: Avg
I94: =L6 -> 20 | J94: =M6 -> 74 | K94: =N6 -> 58.848485
B106: Min, Max and Avg., Mark comparison (Clustered Column Graph)

Sheet IP
A2: Innovative Practice
A3: Course Code - Name | C3: =Theory!C3 -> 22EE401 & POWER GENERATION, TRANSMISSION AND DISTRIBUTION
A4: Faculty ID - Name | C4: =Theory!C4 -> Dr.SIVARAMAN P / EE1329
A5: S. No. | B5: Reg. No. | C5: Name | D5: IP1 | E5: IP2 | F5: IP (16)
A6: =Theory!A6 -> 1 | B6: =Theory!B6 -> 7376231EE102 | C6: =Theory!C6 -> ABINISHA S | D6: =ROUND(F6/2,0) -> 8 | E6: =F6-D6 -> 7 | F6: =Theory!G6 -> 15 | X6: =IF(#REF!<>"",IF(#REF!="A",0,#REF!),"") -> #REF! | Y6: =IF(#REF!<>"",IF(#REF!="A",0,#REF!),"") -> #REF! | Z6: =IF(#REF!<>"",IF(#REF!="A",0,#REF!),"") -> #REF! | AB6: =IF(F6<>"",IF(F6="A",0,F6),"") -> 15
A7: =Theory!A7 -> 2 | B7: =Theory!B7 -> 7376231EE103 | C7: =Theory!C7 -> ANANTHIKA A | D7: =ROUND(F7/2,0) -> 8 | E7: =F7-D7 -> 7 | F7: =Theory!G7 -> 15 | X7: =IF(#REF!<>"",IF(#REF!="A",0,#REF!),"") -> #REF! | Y7: =IF(#REF!<>"",IF(#REF!="A",0,#REF!),"") -> #REF! | Z7: =IF(#REF!<>"",IF(#REF!="A",0,#REF!),"") -> #REF! | AB7: =IF(F7<>"",IF(F7="A",0,F7),"") -> 15
A8: =Theory!A8 -> 3 | B8: =Theory!B8 -> 7376231EE104 | C8: =Theory!C8 -> ANBARASU G | D8: =ROUND(F8/2,0) -> 5 | E8: =F8-D8 -> 4 | F8: =Theory!G8 -> 9 | X8: =IF(#REF!<>"",IF(#REF!="A",0,#REF!),"") -> #REF! | Y8: =IF(#REF!<>"",IF(#REF!="A",0,#REF!),"") -> #REF! | Z8: =IF(#REF!<>"",IF(#REF!="A",0,#REF!),"") -> #REF! | AB8: =IF(F8<>"",IF(F8="A",0,F8),"") -> 9
A9: =Theory!A9 -> 4 | B9: =Theory!B9 -> 7376231EE105 | C9: =Theory!C9 -> ANUJA N | D9: =ROUND(F9/2,0) -> 8 | E9: =F9-D9 -> 7 | F9: =Theory!G9 -> 15 | X9: =IF(#REF!<>"",IF(#REF!="A",0,#REF!),"") -> #REF! | Y9: =IF(#REF!<>"",IF(#REF!="A",0,#REF!),"") -> #REF! | Z9: =IF(#REF!<>"",IF(#REF!="A",0,#REF!),"") -> #REF! | AB9: =IF(F9<>"",IF(F9="A",0,F9),"") -> 15
A10: =Theory!A10 -> 5 | B10: =Theory!B10 -> 7376231EE106 | C10: =Theory!C10 -> ARUN BHAGAVATH S | D10: =ROUND(F10/2,0) -> 7 | E10: =F10-D10 -> 7 | F10: =Theory!G10 -> 14 | X10: =IF(#REF!<>"",IF(#REF!="A",0,#REF!),"") -> #REF! | Y10: =IF(#REF!<>"",IF(#REF!="A",0,#REF!),"") -> #REF! | Z10: =IF(#REF!<>"",IF(#REF!="A",0,#REF!),"") -> #REF! | AB10: =IF(F10<>"",IF(F10="A",0,F10),"") -> 14
A11: =Theory!A11 -> 6 | B11: =Theory!B11 -> 7376231EE107 | C11: =Theory!C11 -> ARUNIKA T K | D11: =ROUND(F11/2,0) -> 8 | E11: =F11-D11 -> 8 | F11: =Theory!G11 -> 16 | X11: =IF(#REF!<>"",IF(#REF!="A",0,#REF!),"") -> #REF! | Y11: =IF(#REF!<>"",IF(#REF!="A",0,#REF!),"") -> #REF! | Z11: =IF(#REF!<>"",IF(#REF!="A",0,#REF!),"") -> #REF! | AB11: =IF(F11<>"",IF(F11="A",0,F11),"") -> 16
A12: =Theory!A12 -> 7 | B12: =Theory!B12 -> 7376231EE108 | C12: =Theory!C12 -> BALAJI M J | D12: =ROUND(F12/2,0) -> 8 | E12: =F12-D12 -> 8 | F12: =Theory!G12 -> 16 | X12: =IF(#REF!<>"",IF(#REF!="A",0,#REF!),"") -> #REF! | Y12: =IF(#REF!<>"",IF(#REF!="A",0,#REF!),"") -> #REF! | Z12: =IF(#REF!<>"",IF(#REF!="A",0,#REF!),"") -> #REF! | AB12: =IF(F12<>"",IF(F12="A",0,F12),"") -> 16
A13: =Theory!A13 -> 8 | B13: =Theory!B13 -> 7376231EE109 | C13: =Theory!C13 -> BHARANIDHARAN S | D13: =ROUND(F13/2,0) -> 8 | E13: =F13-D13 -> 7 | F13: =Theory!G13 -> 15 | X13: =IF(#REF!<>"",IF(#REF!="A",0,#REF!),"") -> #REF! | Y13: =IF(#REF!<>"",IF(#REF!="A",0,#REF!),"") -> #REF! | Z13: =IF(#REF!<>"",IF(#REF!="A",0,#REF!),"") -> #REF! | AB13: =IF(F13<>"",IF(F13="A",0,F13),"") -> 15
A14: =Theory!A14 -> 9 | B14: =Theory!B14 -> 7376231EE110 | C14: =Theory!C14 -> DEEPTHI A | D14: =ROUND(F14/2,0) -> 8 | E14: =F14-D14 -> 8 | F14: =Theory!G14 -> 16 | X14: =IF(#REF!<>"",IF(#REF!="A",0,#REF!),"") -> #REF! | Y14: =IF(#REF!<>"",IF(#REF!="A",0,#REF!),"") -> #REF! | Z14: =IF(#REF!<>"",IF(#REF!="A",0,#REF!),"") -> #REF! | AB14: =IF(F14<>"",IF(F14="A",0,F14),"") -> 16
A15: =Theory!A15 -> 10 | B15: =Theory!B15 -> 7376231EE111 | C15: =Theory!C15 -> DEPEN T | D15: =ROUND(F15/2,0) -> 2 | E15: =F15-D15 -> 1 | F15: =Theory!G15 -> 3 | X15: =IF(#REF!<>"",IF(#REF!="A",0,#REF!),"") -> #REF! | Y15: =IF(#REF!<>"",IF(#REF!="A",0,#REF!),"") -> #REF! | Z15: =IF(#REF!<>"",IF(#REF!="A",0,#REF!),"") -> #REF! | AB15: =IF(F15<>"",IF(F15="A",0,F15),"") -> 3
A16: =Theory!A16 -> 11 | B16: =Theory!B16 -> 7376231EE112 | C16: =Theory!C16 -> DHANUSHA CHITRA PALANISAMY | D16: =ROUND(F16/2,0) -> 7 | E16: =F16-D16 -> 6 | F16: =Theory!G16 -> 13 | X16: =IF(#REF!<>"",IF(#REF!="A",0,#REF!),"") -> #REF! | Y16: =IF(#REF!<>"",IF(#REF!="A",0,#REF!),"") -> #REF! | Z16: =IF(#REF!<>"",IF(#REF!="A",0,#REF!),"") -> #REF! | AB16: =IF(F16<>"",IF(F16="A",0,F16),"") -> 13
A17: =Theory!A17 -> 12 | B17: =Theory!B17 -> 7376231EE113 | C17: =Theory!C17 -> DHARSHINI M | D17: =ROUND(F17/2,0) -> 8 | E17: =F17-D17 -> 7 | F17: =Theory!G17 -> 15 | X17: =IF(#REF!<>"",IF(#REF!="A",0,#REF!),"") -> #REF! | Y17: =IF(#REF!<>"",IF(#REF!="A",0,#REF!),"") -> #REF! | Z17: =IF(#REF!<>"",IF(#REF!="A",0,#REF!),"") -> #REF! | AB17: =IF(F17<>"",IF(F17="A",0,F17),"") -> 15
... A29: =Theory!A29 -> 24 | B29: =Theory!B29 -> 7376231EE125 | C29: =Theory!C29 -> KATHIR NITHESH R | D29: =ROUND(F29/2,0) -> 8 | E29: =F29-D29 -> 7 | F29: =Theory!G29 -> 15 | X29: =IF(#REF!<>"",IF(#REF!="A",0,#REF!),"") -> #REF! | Y29: =IF(#REF!<>"",IF(#REF!="A",0,#REF!),"") -> #REF! | Z29: =IF(#REF!<>"",IF(#REF!="A",0,#REF!),"") -> #REF! | AB29: =IF(F29<>"",IF(F29="A",0,F29),"") -> 15
A30: =Theory!A30 -> 25 | B30: =Theory!B30 -> 7376231EE126 | C30: =Theory!C30 -> KAVITHA M | D30: =ROUND(F30/2,0) -> 8 | E30: =F30-D30 -> 7 | F30: =Theory!G30 -> 15
A31: =Theory!A31 -> 26 | B31: =Theory!B31 -> 7376231EE127 | C31: =Theory!C31 -> KAVIYARASU V K | D31: =ROUND(F31/2,0) -> 7 | E31: =F31-D31 -> 7 | F31: =Theory!G31 -> 14
A32: =Theory!A32 -> 27 | B32: =Theory!B32 -> 7376231EE128 | C32: =Theory!C32 -> KEERTHISANKAR S | D32: =ROUND(F32/2,0) -> 5 | E32: =F32-D32 -> 5 | F32: =Theory!G32 -> 10
A33: =Theory!A33 -> 28 | B33: =Theory!B33 -> 7376231EE129 | C33: =Theory!C33 -> KEERTHIVASAN S | D33: =ROUND(F33/2,0) -> 7 | E33: =F33-D33 -> 7 | F33: =Theory!G33 -> 14
A34: =Theory!A34 -> 29 | B34: =Theory!B34 -> 7376231EE130 | C34: =Theory!C34 -> KHAJA PARVEZ T | D34: =ROUND(F34/2,0) -> 7 | E34: =F34-D34 -> 7 | F34: =Theory!G34 -> 14
A35: =Theory!A35 -> 30 | B35: =Theory!B35 -> 7376231EE131 | C35: =Theory!C35 -> KIRUBA O C | D35: =ROUND(F35/2,0) -> 7 | E35: =F35-D35 -> 7 | F35: =Theory!G35 -> 14
A36: =Theory!A36 -> 31 | B36: =Theory!B36 -> 7376231EE132 | C36: =Theory!C36 -> KOWSHIK ARAVIND K S P | D36: =ROUND(F36/2,0) -> 8 | E36: =F36-D36 -> 8 | F36: =Theory!G36 -> 16
A37: =Theory!A37 -> 32 | B37: =Theory!B37 -> 7376231EE133 | C37: =Theory!C37 -> MANEESH D | D37: =ROUND(F37/2,0) -> 6 | E37: =F37-D37 -> 6 | F37: =Theory!G37 -> 12
A38: =Theory!A38 -> 33 | B38: =Theory!B38 -> 7376231EE134 | C38: =Theory!C38 -> MATHIYARASI K | D38: =ROUND(F38/2,0) -> 8 | E38: =F38-D38 -> 7 | F38: =Theory!G38 -> 15
A39: =Theory!A39 -> 34 | B39: =Theory!B39 -> 7376231EE135 | C39: =Theory!C39 -> MAURYA A S | D39: =ROUND(F39/2,0) -> 8 | E39: =F39-D39 -> 8 | F39: =Theory!G39 -> 16
A40: =Theory!A40 -> 35 | B40: =Theory!B40 -> 7376231EE136 | C40: =Theory!C40 -> MITHUN P P | D40: =ROUND(F40/2,0) -> 8 | E40: =F40-D40 -> 7 | F40: =Theory!G40 -> 15
A41: =Theory!A41 -> 36 | B41: =Theory!B41 -> 7376231EE137 | C41: =Theory!C41 -> MOHAN PRASANTH N | D41: =ROUND(F41/2,0) -> 8 | E41: =F41-D41 -> 8 | F41: =Theory!G41 -> 16
... A71: =Theory!A71 -> 66 | B71: =Theory!B71 -> 7376241EE506 | C71: =Theory!C71 -> VELU PRABHAKARAN M | D71: =ROUND(F71/2,0) -> 7 | E71: =F71-D71 -> 7 | F71: =Theory!G71 -> 14

Sheet Test 1
A1: ='Final Attainment'!A1:V1 -> 0
A2: ='Final Attainment'!A2:V2 -> 0
A4: Academic Year: | C4: ='Final Attainment'!C4 -> 2024-2025 EVEN | E4: Sem & Year: | G4: ='Final Attainment'!G4 -> IV & II | H4: Course Code & Title: | K4: ='Final Attainment'!K4:Q4 -> 22EE401 & POWER GENERATION, TRANSMISSION AND DISTRIBUTION | R4: Faculty: | S4: ='Final Attainment'!S4 -> Dr.SIVARAMAN P / EE1329
A6: PT 1
A7: Scale | B7: ='Final Attainment'!X1 -> CO Attainment Level 0: <50% of students scoring less than the target marks CO Attainment Level 1: 50% of students scoring more than the target marks CO Attainment Level 2: 60% of students scoring more than the target marks CO Attainment Level 3: 70% of students scoring more than the target marks | L7: CO Attainment Summary
R8: CO1 | S8: CO2 | T8: CO3 | U8: CO4 | V8: CO5
L9: Total No. of Students | R9: =COUNTIF(H16:H421,">=0") -> 66 | S9: =COUNTIF(I16:I421,">=0") -> 66 | T9: =COUNTIF(J16:J421,">=0") -> 66 | U9: =COUNTIF(K16:K421,">=0") -> 0 | V9: =COUNTIF(L16:L421,">=0") -> 0
A10: Target CO%: | E10: ='Final Attainment'!E7 -> 58 | L10: Total No. of Students Achieved the Target CO% | R10: =COUNTIF(M16:M421,">="&$E$10) -> 44 | S10: =COUNTIF(N16:N421,">="&$E$10) -> 40 | T10: =COUNTIF(O16:O421,">="&$E$10) -> 47 | U10: =COUNTIF(P16:P421,">="&$E$10) -> 0 | V10: =COUNTIF(Q16:Q421,">="&$E$10) -> 0
A11: Total No. of Students: | E11: =COUNTA(B16:B421) -> 66 | L11: Attainment Level | R11: =IFERROR(__xludf.DUMMYFUNCTION("IF(R10=0,"""",if(CEILING(R10/R9*100)=100,query('Final Attainment'!$H$7:$J$12, ""select H where I<=""&CEILING(R10/R9*100)&"" and J>=""&CEILING(R10/R9*100)&"""" ),query('Final Attainment'!$H$7:$J$12, ""select H where I<=""&CEILING(R10/R9*100)&"" and J>""&"&"CEILING(R10/R9*100)&"""" )))"),2) -> 2 | S11: =IFERROR(__xludf.DUMMYFUNCTION("IF(S10=0,"""",if(CEILING(S10/S9*100)=100,query('Final Attainment'!$H$7:$J$12, ""select H where I<=""&CEILING(S10/S9*100)&"" and J>=""&CEILING(S10/S9*100)&"""" ),query('Final Attainment'!$H$7:$J$12, ""select H where I<=""&CEILING(S10/S9*100)&"" and J>""&"&"CEILING(S10/S9*100)&"""" )))"),2) -> 2 | T11: =IFERROR(__xludf.DUMMYFUNCTION("IF(T10=0,"""",if(CEILING(T10/T9*100)=100,query('Final Attainment'!$H$7:$J$12, ""select H where I<=""&CEILING(T10/T9*100)&"" and J>=""&CEILING(T10/T9*100)&"""" ),query('Final Attainment'!$H$7:$J$12, ""select H where I<=""&CEILING(T10/T9*100)&"" and J>""&"&"CEILING(T10/T9*100)&"""" )))"),3) -> 3 | U11: =IFERROR(__xludf.DUMMYFUNCTION("IF(U10=0,"""",if(CEILING(U10/U9*100)=100,query('Final Attainment'!$H$7:$J$12, ""select H where I<=""&CEILING(U10/U9*100)&"" and J>=""&CEILING(U10/U9*100)&"""" ),query('Final Attainment'!$H$7:$J$12, ""select H where I<=""&CEILING(U10/U9*100)&"" and J>""&"&"CEILING(U10/U9*100)&"""" )))"),"") | V11: =IFERROR(__xludf.DUMMYFUNCTION("IF(V10=0,"""",if(CEILING(V10/V9*100)=100,query('Final Attainment'!$H$7:$J$12, ""select H where I<=""&CEILING(V10/V9*100)&"" and J>=""&CEILING(V10/V9*100)&"""" ),query('Final Attainment'!$H$7:$J$12, ""select H where I<=""&CEILING(V10/V9*100)&"" and J>""&"&"CEILING(V10/V9*100)&"""" )))"),"")
A12: Total No. of Attended Students: | E12: =R9 -> 66 | L12: Total No. of Students who need Remedial Class | R12: =R9-R10 -> 22 | S12: =S9-S10 -> 26 | T12: =T9-T10 -> 19 | U12: =U9-U10 -> 0 | V12: =V9-V10 -> 0
A14: S.No | B14: Reg.No. | C14: MARKS ALLOCATED | H14: MARKS OBTAINED | M14: CO ATTAINMENT % | R14: ATTAINMENT of COs | W14: PT1
C15: CO1 | D15: CO2 | E15: CO3 | F15: CO4 | G15: CO5 | H15: CO1 | I15: CO2 | J15: CO3 | K15: CO4 | L15: CO5 | M15: CO1 | N15: CO2 | O15: CO3 | P15: CO4 | Q15: CO5 | R15: CO1 | S15: CO2 | T15: CO3 | U15: CO4 | V15: CO5 | W15: Marks
A16: =Theory!A6 -> 1 | B16: =Theory!B6 -> 7376231EE102 | C16: 20 | D16: 20 | E16: 10 | H16: 13 | I16: 13 | J16: 7 | M16: =IF(C16="","",H16*100/C16) -> 65 | N16: =IF(D16="","",I16*100/D16) -> 65 | O16: =IF(E16="","",J16*100/E16) -> 70 | P16: =IF(F16="","",K16*100/F16) | Q16: =IF(G16="","",L16*100/G16) | R16: =IF(M16>=$E$10,"1","0") -> 1 | S16: =IF(N16>=$E$10,"1","0") -> 1 | T16: =IF(O16>=$E$10,"1","0") -> 1 | W16: =Theory!D6 -> 33
A17: =Theory!A7 -> 2 | B17: =Theory!B7 -> 7376231EE103 | C17: 20 | D17: 20 | E17: 10 | H17: 13 | I17: 13 | J17: 7 | M17: =IF(C17="","",H17*100/C17) -> 65 | N17: =IF(D17="","",I17*100/D17) -> 65 | O17: =IF(E17="","",J17*100/E17) -> 70 | P17: =IF(F17="","",K17*100/F17) | Q17: =IF(G17="","",L17*100/G17) | R17: =IF(M17>=$E$10,"1","0") -> 1 | S17: =IF(N17>=$E$10,"1","0") -> 1 | T17: =IF(O17>=$E$10,"1","0") -> 1 | W17: =Theory!D7 -> 33
A18: =Theory!A8 -> 3 | B18: =Theory!B8 -> 7376231EE104 | C18: 20 | D18: 20 | E18: 10 | H18: 7 | I18: 7 | J18: 4 | M18: =IF(C18="","",H18*100/C18) -> 35 | N18: =IF(D18="","",I18*100/D18) -> 35 | O18: =IF(E18="","",J18*100/E18) -> 40 | P18: =IF(F18="","",K18*100/F18) | Q18: =IF(G18="","",L18*100/G18) | R18: =IF(M18>=$E$10,"1","0") -> 0 | S18: =IF(N18>=$E$10,"1","0") -> 0 | T18: =IF(O18>=$E$10,"1","0") -> 0 | W18: =Theory!D8 -> 18
A19: =Theory!A9 -> 4 | B19: =Theory!B9 -> 7376231EE105 | C19: 20 | D19: 20 | E19: 10 | H19: 14 | I19: 14 | J19: 6 | M19: =IF(C19="","",H19*100/C19) -> 70 | N19: =IF(D19="","",I19*100/D19) -> 70 | O19: =IF(E19="","",J19*100/E19) -> 60 | P19: =IF(F19="","",K19*100/F19) | Q19: =IF(G19="","",L19*100/G19) | R19: =IF(M19>=$E$10,"1","0") -> 1 | S19: =IF(N19>=$E$10,"1","0") -> 1 | T19: =IF(O19>=$E$10,"1","0") -> 1 | W19: =Theory!D9 -> 34
A20: =Theory!A10 -> 5 | B20: =Theory!B10 -> 7376231EE106 | C20: 20 | D20: 20 | E20: 10 | H20: 13 | I20: 13 | J20: 6 | M20: =IF(C20="","",H20*100/C20) -> 65 | N20: =IF(D20="","",I20*100/D20) -> 65 | O20: =IF(E20="","",J20*100/E20) -> 60 | P20: =IF(F20="","",K20*100/F20) | Q20: =IF(G20="","",L20*100/G20) | R20: =IF(M20>=$E$10,"1","0") -> 1 | S20: =IF(N20>=$E$10,"1","0") -> 1 | T20: =IF(O20>=$E$10,"1","0") -> 1 | W20: =Theory!D10 -> 32
A21: =Theory!A11 -> 6 | B21: =Theory!B11 -> 7376231EE107 | C21: 20 | D21: 20 | E21: 10 | H21: 14 | I21: 14 | J21: 6 | M21: =IF(C21="","",H21*100/C21) -> 70 | N21: =IF(D21="","",I21*100/D21) -> 70 | O21: =IF(E21="","",J21*100/E21) -> 60 | P21: =IF(F21="","",K21*100/F21) | Q21: =IF(G21="","",L21*100/G21) | R21: =IF(M21>=$E$10,"1","0") -> 1 | S21: =IF(N21>=$E$10,"1","0") -> 1 | T21: =IF(O21>=$E$10,"1","0") -> 1 | W21: =Theory!D11 -> 34
A22: =Theory!A12 -> 7 | B22: =Theory!B12 -> 7376231EE108 | C22: 20 | D22: 20 | E22: 10 | H22: 14 | I22: 14 | J22: 6 | M22: =IF(C22="","",H22*100/C22) -> 70 | N22: =IF(D22="","",I22*100/D22) -> 70 | O22: =IF(E22="","",J22*100/E22) -> 60 | P22: =IF(F22="","",K22*100/F22) | Q22: =IF(G22="","",L22*100/G22) | R22: =IF(M22>=$E$10,"1","0") -> 1 | S22: =IF(N22>=$E$10,"1","0") -> 1 | T22: =IF(O22>=$E$10,"1","0") -> 1 | W22: =Theory!D12 -> 34
A23: =Theory!A13 -> 8 | B23: =Theory!B13 -> 7376231EE109 | C23: 20 | D23: 20 | E23: 10 | H23: 13 | I23: 13 | J23: 7 | M23: =IF(C23="","",H23*100/C23) -> 65 | N23: =IF(D23="","",I23*100/D23) -> 65 | O23: =IF(E23="","",J23*100/E23) -> 70 | P23: =IF(F23="","",K23*100/F23) | Q23: =IF(G23="","",L23*100/G23) | R23: =IF(M23>=$E$10,"1","0") -> 1 | S23: =IF(N23>=$E$10,"1","0") -> 1 | T23: =IF(O23>=$E$10,"1","0") -> 1 | W23: =Theory!D13 -> 33
A24: =Theory!A14 -> 9 | B24: =Theory!B14 -> 7376231EE110 | C24: 20 | D24: 20 | E24: 10 | H24: 15 | I24: 14 | J24: 7 | M24: =IF(C24="","",H24*100/C24) -> 75 | N24: =IF(D24="","",I24*100/D24) -> 70 | O24: =IF(E24="","",J24*100/E24) -> 70 | P24: =IF(F24="","",K24*100/F24) | Q24: =IF(G24="","",L24*100/G24) | R24: =IF(M24>=$E$10,"1","0") -> 1 | S24: =IF(N24>=$E$10,"1","0") -> 1 | T24: =IF(O24>=$E$10,"1","0") -> 1 | W24: =Theory!D14 -> 36
A25: =Theory!A15 -> 10 | B25: =Theory!B15 -> 7376231EE111 | C25: 20 | D25: 20 | E25: 10 | H25: 6 | I25: 5 | J25: 3 | M25: =IF(C25="","",H25*100/C25) -> 30 | N25: =IF(D25="","",I25*100/D25) -> 25 | O25: =IF(E25="","",J25*100/E25) -> 30 | P25: =IF(F25="","",K25*100/F25) | Q25: =IF(G25="","",L25*100/G25) | R25: =IF(M25>=$E$10,"1","0") -> 0 | S25: =IF(N25>=$E$10,"1","0") -> 0 | T25: =IF(O25>=$E$10,"1","0") -> 0 | W25: =Theory!D15 -> 14
A26: =Theory!A16 -> 11 | B26: =Theory!B16 -> 7376231EE112 | C26: 20 | D26: 20 | E26: 10 | H26: 13 | I26: 13 | J26: 6 | M26: =IF(C26="","",H26*100/C26) -> 65 | N26: =IF(D26="","",I26*100/D26) -> 65 | O26: =IF(E26="","",J26*100/E26) -> 60 | P26: =IF(F26="","",K26*100/F26) | Q26: =IF(G26="","",L26*100/G26) | R26: =IF(M26>=$E$10,"1","0") -> 1 | S26: =IF(N26>=$E$10,"1","0") -> 1 | T26: =IF(O26>=$E$10,"1","0") -> 1 | W26: =Theory!D16 -> 32
A27: =Theory!A17 -> 12 | B27: =Theory!B17 -> 7376231EE113 | C27: 20 | D27: 20 | E27: 10 | H27: 12 | I27: 13 | J27: 5 | M27: =IF(C27="","",H27*100/C27) -> 60 | N27: =IF(D27="","",I27*100/D27) -> 65 | O27: =IF(E27="","",J27*100/E27) -> 50 | P27: =IF(F27="","",K27*100/F27) | Q27: =IF(G27="","",L27*100/G27) | R27: =IF(M27>=$E$10,"1","0") -> 1 | S27: =IF(N27>=$E$10,"1","0") -> 1 | T27: =IF(O27>=$E$10,"1","0") -> 0 | W27: =Theory!D17 -> 30
... A81: =Theory!A71 -> 66 | B81: =Theory!B71 -> 7376241EE506 | C81: 20 | D81: 20 | E81: 10 | H81: 11 | I81: 11 | J81: 5 | M81: =IF(C81="","",H81*100/C81) -> 55 | N81: =IF(D81="","",I81*100/D81) -> 55 | O81: =IF(E81="","",J81*100/E81) -> 50 | P81: =IF(F81="","",K81*100/F81) | Q81: =IF(G81="","",L81*100/G81) | R81: =IF(M81>=$E$10,"1","0") -> 0 | S81: =IF(N81>=$E$10,"1","0") -> 0 | T81: =IF(O81>=$E$10,"1","0") -> 0 | W81: =Theory!D71 -> 27

Sheet Test 2
A1: ='Final Attainment'!A1:V1 -> 0
A2: ='Final Attainment'!A2:V2 -> 0
A4: Academic Year: | C4: ='Final Attainment'!C4 -> 2024-2025 EVEN | E4: Sem & Year: | G4: ='Final Attainment'!G4 -> IV & II | H4: Course Code & Title: | K4: ='Final Attainment'!K4:Q4 -> 22EE401 & POWER GENERATION, TRANSMISSION AND DISTRIBUTION | R4: Faculty: | S4: ='Final Attainment'!S4 -> Dr.SIVARAMAN P / EE1329
A6: PT 2
A7: Scale | B7: ='Final Attainment'!X1 -> CO Attainment Level 0: <50% of students scoring less than the target marks CO Attainment Level 1: 50% of students scoring more than the target marks CO Attainment Level 2: 60% of students scoring more than the target marks CO Attainment Level 3: 70% of students scoring more than the target marks | L7: CO Attainment Summary
R8: CO1 | S8: CO2 | T8: CO3 | U8: CO4 | V8: CO5
L9: Total No. of Students | R9: =COUNTIF(H16:H472,">=0") -> 0 | S9: =COUNTIF(I16:I472,">=0") -> 0 | T9: =COUNTIF(J16:J472,">=0") -> 66 | U9: =COUNTIF(K16:K472,">=0") -> 66 | V9: =COUNTIF(L16:L472,">=0") -> 66
A10: Target CO%: | E10: ='Final Attainment'!E7 -> 58 | L10: Total No. of Students Achieved the Target CO% | R10: =COUNTIF(M16:M472,">="&$E$10) -> 0 | S10: =COUNTIF(N16:N472,">="&$E$10) -> 0 | T10: =COUNTIF(O16:O472,">="&$E$10) -> 48 | U10: =COUNTIF(P16:P472,">="&$E$10) -> 42 | V10: =COUNTIF(Q16:Q472,">="&$E$10) -> 44
A11: Total No. of Students: | E11: =COUNTA(B16:B472) -> 66 | L11: Attainment Level | R11: =IFERROR(__xludf.DUMMYFUNCTION("IF(R10=0,"""",if(CEILING(R10/R9*100)=100,query('Final Attainment'!$H$7:$J$12, ""select H where I<=""&CEILING(R10/R9*100)&"" and J>=""&CEILING(R10/R9*100)&"""" ),query('Final Attainment'!$H$7:$J$12, ""select H where I<=""&CEILING(R10/R9*100)&"" and J>""&"&"CEILING(R10/R9*100)&"""" )))"),"") | S11: =IFERROR(__xludf.DUMMYFUNCTION("IF(S10=0,"""",if(CEILING(S10/S9*100)=100,query('Final Attainment'!$H$7:$J$12, ""select H where I<=""&CEILING(S10/S9*100)&"" and J>=""&CEILING(S10/S9*100)&"""" ),query('Final Attainment'!$H$7:$J$12, ""select H where I<=""&CEILING(S10/S9*100)&"" and J>""&"&"CEILING(S10/S9*100)&"""" )))"),"") | T11: =IFERROR(__xludf.DUMMYFUNCTION("IF(T10=0,"""",if(CEILING(T10/T9*100)=100,query('Final Attainment'!$H$7:$J$12, ""select H where I<=""&CEILING(T10/T9*100)&"" and J>=""&CEILING(T10/T9*100)&"""" ),query('Final Attainment'!$H$7:$J$12, ""select H where I<=""&CEILING(T10/T9*100)&"" and J>""&"&"CEILING(T10/T9*100)&"""" )))"),3) -> 3 | U11: =IFERROR(__xludf.DUMMYFUNCTION("IF(U10=0,"""",if(CEILING(U10/U9*100)=100,query('Final Attainment'!$H$7:$J$12, ""select H where I<=""&CEILING(U10/U9*100)&"" and J>=""&CEILING(U10/U9*100)&"""" ),query('Final Attainment'!$H$7:$J$12, ""select H where I<=""&CEILING(U10/U9*100)&"" and J>""&"&"CEILING(U10/U9*100)&"""" )))"),2) -> 2 | V11: =IFERROR(__xludf.DUMMYFUNCTION("IF(V10=0,"""",if(CEILING(V10/V9*100)=100,query('Final Attainment'!$H$7:$J$12, ""select H where I<=""&CEILING(V10/V9*100)&"" and J>=""&CEILING(V10/V9*100)&"""" ),query('Final Attainment'!$H$7:$J$12, ""select H where I<=""&CEILING(V10/V9*100)&"" and J>""&"&"CEILING(V10/V9*100)&"""" )))"),2) -> 2
A12: Total No. of Attended Students: | E12: =T9 -> 66 | L12: Total No. of Students who need Remedial Class | R12: =R9-R10 -> 0 | S12: =S9-S10 -> 0 | T12: =T9-T10 -> 18 | U12: =U9-U10 -> 24 | V12: =V9-V10 -> 22
A14: S.No | B14: Reg.No. | C14: MARKS ALLOCATED | H14: MARKS OBTAINED | M14: CO ATTAINMENT % | R14: ATTAINMENT of COs | W14: PT2
C15: CO1 | D15: CO2 | E15: CO3 | F15: CO4 | G15: CO5 | H15: CO1 | I15: CO2 | J15: CO3 | K15: CO4 | L15: CO5 | M15: CO1 | N15: CO2 | O15: CO3 | P15: CO4 | Q15: CO5 | R15: CO1 | S15: CO2 | T15: CO3 | U15: CO4 | V15: CO5 | W15: Marks
A16: =Theory!A6 -> 1 | B16: =Theory!B6 -> 7376231EE102 | E16: 10 | F16: 20 | G16: 20 | J16: 7 | K16: 14 | L16: 14 | N16: =IF(D16="","",I16*100/D16) | O16: =IF(E16="","",J16*100/E16) -> 70 | P16: =IF(F16="","",K16*100/F16) -> 70 | Q16: =IF(G16="","",L16*100/G16) -> 70 | T16: =IF(O16>=$E$10,"1","0") -> 1 | U16: =IF(P16>=$E$10,"1","0") -> 1 | V16: =IF(Q16>=$E$10,"1","0") -> 1 | W16: =Theory!E6 -> 35
A17: =Theory!A7 -> 2 | B17: =Theory!B7 -> 7376231EE103 | E17: 10 | F17: 20 | G17: 20 | J17: 6 | K17: 14 | L17: 14 | N17: =IF(D17="","",I17*100/D17) | O17: =IF(E17="","",J17*100/E17) -> 60 | P17: =IF(F17="","",K17*100/F17) -> 70 | Q17: =IF(G17="","",L17*100/G17) -> 70 | T17: =IF(O17>=$E$10,"1","0") -> 1 | U17: =IF(P17>=$E$10,"1","0") -> 1 | V17: =IF(Q17>=$E$10,"1","0") -> 1 | W17: =Theory!E7 -> 34
A18: =Theory!A8 -> 3 | B18: =Theory!B8 -> 7376231EE104 | E18: 10 | F18: 20 | G18: 20 | J18: 5 | K18: 9 | L18: 9 | N18: =IF(D18="","",I18*100/D18) | O18: =IF(E18="","",J18*100/E18) -> 50 | P18: =IF(F18="","",K18*100/F18) -> 45 | Q18: =IF(G18="","",L18*100/G18) -> 45 | T18: =IF(O18>=$E$10,"1","0") -> 0 | U18: =IF(P18>=$E$10,"1","0") -> 0 | V18: =IF(Q18>=$E$10,"1","0") -> 0 | W18: =Theory!E8 -> 23
A19: =Theory!A9 -> 4 | B19: =Theory!B9 -> 7376231EE105 | E19: 10 | F19: 20 | G19: 20 | J19: 7 | K19: 13 | L19: 13 | N19: =IF(D19="","",I19*100/D19) | O19: =IF(E19="","",J19*100/E19) -> 70 | P19: =IF(F19="","",K19*100/F19) -> 65 | Q19: =IF(G19="","",L19*100/G19) -> 65 | T19: =IF(O19>=$E$10,"1","0") -> 1 | U19: =IF(P19>=$E$10,"1","0") -> 1 | V19: =IF(Q19>=$E$10,"1","0") -> 1 | W19: =Theory!E9 -> 33
A20: =Theory!A10 -> 5 | B20: =Theory!B10 -> 7376231EE106 | E20: 10 | F20: 20 | G20: 20 | J20: 6 | K20: 13 | L20: 13 | N20: =IF(D20="","",I20*100/D20) | O20: =IF(E20="","",J20*100/E20) -> 60 | P20: =IF(F20="","",K20*100/F20) -> 65 | Q20: =IF(G20="","",L20*100/G20) -> 65 | T20: =IF(O20>=$E$10,"1","0") -> 1 | U20: =IF(P20>=$E$10,"1","0") -> 1 | V20: =IF(Q20>=$E$10,"1","0") -> 1 | W20: =Theory!E10 -> 32
A21: =Theory!A11 -> 6 | B21: =Theory!B11 -> 7376231EE107 | E21: 10 | F21: 20 | G21: 20 | J21: 6 | K21: 14 | L21: 14 | N21: =IF(D21="","",I21*100/D21) | O21: =IF(E21="","",J21*100/E21) -> 60 | P21: =IF(F21="","",K21*100/F21) -> 70 | Q21: =IF(G21="","",L21*100/G21) -> 70 | T21: =IF(O21>=$E$10,"1","0") -> 1 | U21: =IF(P21>=$E$10,"1","0") -> 1 | V21: =IF(Q21>=$E$10,"1","0") -> 1 | W21: =Theory!E11 -> 34
A22: =Theory!A12 -> 7 | B22: =Theory!B12 -> 7376231EE108 | E22: 10 | F22: 20 | G22: 20 | J22: 6 | K22: 13 | L22: 13 | N22: =IF(D22="","",I22*100/D22) | O22: =IF(E22="","",J22*100/E22) -> 60 | P22: =IF(F22="","",K22*100/F22) -> 65 | Q22: =IF(G22="","",L22*100/G22) -> 65 | T22: =IF(O22>=$E$10,"1","0") -> 1 | U22: =IF(P22>=$E$10,"1","0") -> 1 | V22: =IF(Q22>=$E$10,"1","0") -> 1 | W22: =Theory!E12 -> 32
A23: =Theory!A13 -> 8 | B23: =Theory!B13 -> 7376231EE109 | E23: 10 | F23: 20 | G23: 20 | J23: 6 | K23: 13 | L23: 13 | N23: =IF(D23="","",I23*100/D23) | O23: =IF(E23="","",J23*100/E23) -> 60 | P23: =IF(F23="","",K23*100/F23) -> 65 | Q23: =IF(G23="","",L23*100/G23) -> 65 | T23: =IF(O23>=$E$10,"1","0") -> 1 | U23: =IF(P23>=$E$10,"1","0") -> 1 | V23: =IF(Q23>=$E$10,"1","0") -> 1 | W23: =Theory!E13 -> 32
A24: =Theory!A14 -> 9 | B24: =Theory!B14 -> 7376231EE110 | E24: 10 | F24: 20 | G24: 20 | J24: 6 | K24: 15 | L24: 16 | N24: =IF(D24="","",I24*100/D24) | O24: =IF(E24="","",J24*100/E24) -> 60 | P24: =IF(F24="","",K24*100/F24) -> 75 | Q24: =IF(G24="","",L24*100/G24) -> 80 | T24: =IF(O24>=$E$10,"1","0") -> 1 | U24: =IF(P24>=$E$10,"1","0") -> 1 | V24: =IF(Q24>=$E$10,"1","0") -> 1 | W24: =Theory!E14 -> 37
A25: =Theory!A15 -> 10 | B25: =Theory!B15 -> 7376231EE111 | E25: 10 | F25: 20 | G25: 20 | J25: 3 | K25: 5 | L25: 4 | N25: =IF(D25="","",I25*100/D25) | O25: =IF(E25="","",J25*100/E25) -> 30 | P25: =IF(F25="","",K25*100/F25) -> 25 | Q25: =IF(G25="","",L25*100/G25) -> 20 | T25: =IF(O25>=$E$10,"1","0") -> 0 | U25: =IF(P25>=$E$10,"1","0") -> 0 | V25: =IF(Q25>=$E$10,"1","0") -> 0 | W25: =Theory!E15 -> 12
A26: =Theory!A16 -> 11 | B26: =Theory!B16 -> 7376231EE112 | E26: 10 | F26: 20 | G26: 20 | J26: 6 | K26: 11 | L26: 11 | N26: =IF(D26="","",I26*100/D26) | O26: =IF(E26="","",J26*100/E26) -> 60 | P26: =IF(F26="","",K26*100/F26) -> 55 | Q26: =IF(G26="","",L26*100/G26) -> 55 | T26: =IF(O26>=$E$10,"1","0") -> 1 | U26: =IF(P26>=$E$10,"1","0") -> 0 | V26: =IF(Q26>=$E$10,"1","0") -> 0 | W26: =Theory!E16 -> 28
A27: =Theory!A17 -> 12 | B27: =Theory!B17 -> 7376231EE113 | E27: 10 | F27: 20 | G27: 20 | J27: 6 | K27: 14 | L27: 14 | N27: =IF(D27="","",I27*100/D27) | O27: =IF(E27="","",J27*100/E27) -> 60 | P27: =IF(F27="","",K27*100/F27) -> 70 | Q27: =IF(G27="","",L27*100/G27) -> 70 | T27: =IF(O27>=$E$10,"1","0") -> 1 | U27: =IF(P27>=$E$10,"1","0") -> 1 | V27: =IF(Q27>=$E$10,"1","0") -> 1 | W27: =Theory!E17 -> 34
... A81: =Theory!A71 -> 66 | B81: =Theory!B71 -> 7376241EE506 | E81: 10 | F81: 20 | G81: 20 | J81: 6 | K81: 13 | L81: 13 | N81: =IF(D81="","",I81*100/D81) | O81: =IF(E81="","",J81*100/E81) -> 60 | P81: =IF(F81="","",K81*100/F81) -> 65 | Q81: =IF(G81="","",L81*100/G81) -> 65 | T81: =IF(O81>=$E$10,"1","0") -> 1 | U81: =IF(P81>=$E$10,"1","0") -> 1 | V81: =IF(Q81>=$E$10,"1","0") -> 1 | W81: =Theory!E71 -> 32

Sheet IP1
A1: ='Final Attainment'!A1:V1 -> 0
A2: ='Final Attainment'!A2:V2 -> 0
A4: Academic Year: | C4: ='Final Attainment'!C4 -> 2024-2025 EVEN | E4: Sem & Year: | G4: ='Final Attainment'!G4 -> IV & II | H4: Course Code & Title: | K4: ='Final Attainment'!K4:Q4 -> 22EE401 & POWER GENERATION, TRANSMISSION AND DISTRIBUTION | R4: Faculty: | S4: ='Final Attainment'!S4 -> Dr.SIVARAMAN P / EE1329
A6: IP1
A7: Scale | B7: ='Final Attainment'!X1 -> CO Attainment Level 0: <50% of students scoring less than the target marks CO Attainment Level 1: 50% of students scoring more than the target marks CO Attainment Level 2: 60% of students scoring more than the target marks CO Attainment Level 3: 70% of students scoring more than the target marks | L7: CO Attainment Summary
R8: CO1 | S8: CO2 | T8: CO3 | U8: CO4 | V8: CO5
L9: Total No. of Students | R9: =COUNTIF(H16:H542,">=0") -> 66 | S9: =COUNTIF(I16:I542,">=0") -> 0 | T9: =COUNTIF(J16:J542,">=0") -> 0 | U9: =COUNTIF(K16:K542,">=0") -> 0 | V9: =COUNTIF(L16:L542,">=0") -> 0
A10: Target CO%: | E10: ='Final Attainment'!E7 -> 58 | L10: Total No. of Students Achieved the Target CO% | R10: =COUNTIF(M16:M542,">="&$E$10) -> 63 | S10: =COUNTIF(N16:N542,">="&$E$10) -> 0 | T10: =COUNTIF(O16:O542,">="&$E$10) -> 0 | U10: =COUNTIF(P16:P542,">="&$E$10) -> 0 | V10: =COUNTIF(Q16:Q542,">="&$E$10) -> 0
A11: Total No. of Students: | E11: =COUNTA(B16:B542) -> 66 | L11: Attainment Level | R11: =IFERROR(__xludf.DUMMYFUNCTION("IF(R10=0,"""",if(CEILING(R10/R9*100)=100,query('Final Attainment'!$H$7:$J$12, ""select H where I<=""&CEILING(R10/R9*100)&"" and J>=""&CEILING(R10/R9*100)&"""" ),query('Final Attainment'!$H$7:$J$12, ""select H where I<=""&CEILING(R10/R9*100)&"" and J>""&"&"CEILING(R10/R9*100)&"""" )))"),3) -> 3 | S11: =IFERROR(__xludf.DUMMYFUNCTION("IF(S10=0,"""",if(CEILING(S10/S9*100)=100,query('Final Attainment'!$H$7:$J$12, ""select H where I<=""&CEILING(S10/S9*100)&"" and J>=""&CEILING(S10/S9*100)&"""" ),query('Final Attainment'!$H$7:$J$12, ""select H where I<=""&CEILING(S10/S9*100)&"" and J>""&"&"CEILING(S10/S9*100)&"""" )))"),"") | T11: =IFERROR(__xludf.DUMMYFUNCTION("IF(T10=0,"""",if(CEILING(T10/T9*100)=100,query('Final Attainment'!$H$7:$J$12, ""select H where I<=""&CEILING(T10/T9*100)&"" and J>=""&CEILING(T10/T9*100)&"""" ),query('Final Attainment'!$H$7:$J$12, ""select H where I<=""&CEILING(T10/T9*100)&"" and J>""&"&"CEILING(T10/T9*100)&"""" )))"),"") | U11: =IFERROR(__xludf.DUMMYFUNCTION("IF(U10=0,"""",if(CEILING(U10/U9*100)=100,query('Final Attainment'!$H$7:$J$12, ""select H where I<=""&CEILING(U10/U9*100)&"" and J>=""&CEILING(U10/U9*100)&"""" ),query('Final Attainment'!$H$7:$J$12, ""select H where I<=""&CEILING(U10/U9*100)&"" and J>""&"&"CEILING(U10/U9*100)&"""" )))"),"") | V11: =IFERROR(__xludf.DUMMYFUNCTION("IF(V10=0,"""",if(CEILING(V10/V9*100)=100,query('Final Attainment'!$H$7:$J$12, ""select H where I<=""&CEILING(V10/V9*100)&"" and J>=""&CEILING(V10/V9*100)&"""" ),query('Final Attainment'!$H$7:$J$12, ""select H where I<=""&CEILING(V10/V9*100)&"" and J>""&"&"CEILING(V10/V9*100)&"""" )))"),"")
A12: Total No. of Attended Students: | E12: =R9 -> 66 | L12: Total No. of Students who need Remedial Class | R12: =R9-R10 -> 3 | S12: =S9-S10 -> 0 | T12: =T9-T10 -> 0 | U12: =U9-U10 -> 0 | V12: =V9-V10 -> 0
A14: S.No | B14: Reg.No. | C14: MARKS ALLOCATED | H14: MARKS OBTAINED | M14: CO ATTAINMENT % | R14: ATTAINMENT of COs | W14: IP1
C15: CO1 | D15: CO2 | E15: CO3 | F15: CO4 | G15: CO5 | H15: CO1 | I15: CO2 | J15: CO3 | K15: CO4 | L15: CO5 | M15: CO1 | N15: CO2 | O15: CO3 | P15: CO4 | Q15: CO5 | R15: CO1 | S15: CO2 | T15: CO3 | U15: CO4 | V15: CO5 | W15: Marks
A16: =Theory!A6 -> 1 | B16: =Theory!B6 -> 7376231EE102 | C16: 8 | H16: 8 | M16: =IF(C16="","",H16*100/C16) -> 100 | N16: =IF(D16="","",I16*100/D16) | O16: =IF(E16="","",J16*100/E16) | P16: =IF(F16="","",K16*100/F16) | Q16: =IF(G16="","",L16*100/G16) | W16: =IP!D6 -> 8
A17: =Theory!A7 -> 2 | B17: =Theory!B7 -> 7376231EE103 | C17: 8 | H17: 8 | M17: =IF(C17="","",H17*100/C17) -> 100 | N17: =IF(D17="","",I17*100/D17) | O17: =IF(E17="","",J17*100/E17) | P17: =IF(F17="","",K17*100/F17) | Q17: =IF(G17="","",L17*100/G17) | W17: =IP!D7 -> 8
A18: =Theory!A8 -> 3 | B18: =Theory!B8 -> 7376231EE104 | C18: 8 | H18: 5 | M18: =IF(C18="","",H18*100/C18) -> 62.5 | N18: =IF(D18="","",I18*100/D18) | O18: =IF(E18="","",J18*100/E18) | P18: =IF(F18="","",K18*100/F18) | Q18: =IF(G18="","",L18*100/G18) | W18: =IP!D8 -> 5
A19: =Theory!A9 -> 4 | B19: =Theory!B9 -> 7376231EE105 | C19: 8 | H19: 8 | M19: =IF(C19="","",H19*100/C19) -> 100 | N19: =IF(D19="","",I19*100/D19) | O19: =IF(E19="","",J19*100/E19) | P19: =IF(F19="","",K19*100/F19) | Q19: =IF(G19="","",L19*100/G19) | W19: =IP!D9 -> 8
A20: =Theory!A10 -> 5 | B20: =Theory!B10 -> 7376231EE106 | C20: 8 | H20: 7 | M20: =IF(C20="","",H20*100/C20) -> 87.5 | N20: =IF(D20="","",I20*100/D20) | O20: =IF(E20="","",J20*100/E20) | P20: =IF(F20="","",K20*100/F20) | Q20: =IF(G20="","",L20*100/G20) | W20: =IP!D10 -> 7
A21: =Theory!A11 -> 6 | B21: =Theory!B11 -> 7376231EE107 | C21: 8 | H21: 8 | M21: =IF(C21="","",H21*100/C21) -> 100 | N21: =IF(D21="","",I21*100/D21) | O21: =IF(E21="","",J21*100/E21) | P21: =IF(F21="","",K21*100/F21) | Q21: =IF(G21="","",L21*100/G21) | W21: =IP!D11 -> 8
A22: =Theory!A12 -> 7 | B22: =Theory!B12 -> 7376231EE108 | C22: 8 | H22: 8 | M22: =IF(C22="","",H22*100/C22) -> 100 | N22: =IF(D22="","",I22*100/D22) | O22: =IF(E22="","",J22*100/E22) | P22: =IF(F22="","",K22*100/F22) | Q22: =IF(G22="","",L22*100/G22) | W22: =IP!D12 -> 8
A23: =Theory!A13 -> 8 | B23: =Theory!B13 -> 7376231EE109 | C23: 8 | H23: 8 | M23: =IF(C23="","",H23*100/C23) -> 100 | N23: =IF(D23="","",I23*100/D23) | O23: =IF(E23="","",J23*100/E23) | P23: =IF(F23="","",K23*100/F23) | Q23: =IF(G23="","",L23*100/G23) | W23: =IP!D13 -> 8
A24: =Theory!A14 -> 9 | B24: =Theory!B14 -> 7376231EE110 | C24: 8 | H24: 8 | M24: =IF(C24="","",H24*100/C24) -> 100 | N24: =IF(D24="","",I24*100/D24) | O24: =IF(E24="","",J24*100/E24) | P24: =IF(F24="","",K24*100/F24) | Q24: =IF(G24="","",L24*100/G24) | W24: =IP!D14 -> 8
A25: =Theory!A15 -> 10 | B25: =Theory!B15 -> 7376231EE111 | C25: 8 | H25: 2 | M25: =IF(C25="","",H25*100/C25) -> 25 | N25: =IF(D25="","",I25*100/D25) | O25: =IF(E25="","",J25*100/E25) | P25: =IF(F25="","",K25*100/F25) | Q25: =IF(G25="","",L25*100/G25) | W25: =IP!D15 -> 2
A26: =Theory!A16 -> 11 | B26: =Theory!B16 -> 7376231EE112 | C26: 8 | H26: 7 | M26: =IF(C26="","",H26*100/C26) -> 87.5 | N26: =IF(D26="","",I26*100/D26) | O26: =IF(E26="","",J26*100/E26) | P26: =IF(F26="","",K26*100/F26) | Q26: =IF(G26="","",L26*100/G26) | W26: =IP!D16 -> 7
A27: =Theory!A17 -> 12 | B27: =Theory!B17 -> 7376231EE113 | C27: 8 | H27: 8 | M27: =IF(C27="","",H27*100/C27) -> 100 | N27: =IF(D27="","",I27*100/D27) | O27: =IF(E27="","",J27*100/E27) | P27: =IF(F27="","",K27*100/F27) | Q27: =IF(G27="","",L27*100/G27) | W27: =IP!D17 -> 8
... A81: =Theory!A71 -> 66 | B81: =Theory!B71 -> 7376241EE506 | C81: 8 | H81: 7 | M81: =IF(C81="","",H81*100/C81) -> 87.5 | N81: =IF(D81="","",I81*100/D81) | O81: =IF(E81="","",J81*100/E81) | P81: =IF(F81="","",K81*100/F81) | Q81: =IF(G81="","",L81*100/G81) | W81: =IP!D71 -> 7

Sheet IP2
A1: ='Final Attainment'!A1:V1 -> 0
A2: ='Final Attainment'!A2:V2 -> 0
A4: Academic Year: | C4: ='Final Attainment'!C4 -> 2024-2025 EVEN | E4: Sem & Year: | G4: ='Final Attainment'!G4 -> IV & II | H4: Course Code & Title: | K4: ='Final Attainment'!K4:Q4 -> 22EE401 & POWER GENERATION, TRANSMISSION AND DISTRIBUTION | R4: Faculty: | S4: ='Final Attainment'!S4 -> Dr.SIVARAMAN P / EE1329
A6: IP2
A7: Scale | B7: ='Final Attainment'!X1 -> CO Attainment Level 0: <50% of students scoring less than the target marks CO Attainment Level 1: 50% of students scoring more than the target marks CO Attainment Level 2: 60% of students scoring more than the target marks CO Attainment Level 3: 70% of students scoring more than the target marks | L7: CO Attainment Summary
R8: CO1 | S8: CO2 | T8: CO3 | U8: CO4 | V8: CO5
L9: Total No. of Students | R9: =COUNTIF(H16:H548,">=0") -> 0 | S9: =COUNTIF(I16:I548,">=0") -> 0 | T9: =COUNTIF(J16:J548,">=0") -> 0 | U9: =COUNTIF(K16:K548,">=0") -> 66 | V9: =COUNTIF(L16:L548,">=0") -> 0
A10: Target CO%: | E10: ='Final Attainment'!E7 -> 58 | L10: Total No. of Students Achieved the Target CO% | R10: =COUNTIF(M16:M548,">="&$E$10) -> 0 | S10: =COUNTIF(N16:N548,">="&$E$10) -> 0 | T10: =COUNTIF(O16:O548,">="&$E$10) -> 0 | U10: =COUNTIF(P16:P548,">="&$E$10) -> 58 | V10: =COUNTIF(Q16:Q548,">="&$E$10) -> 0
A11: Total No. of Students: | E11: =COUNTA(B16:B548) -> 66 | L11: Attainment Level | R11: =IFERROR(__xludf.DUMMYFUNCTION("IF(R10=0,"""",if(CEILING(R10/R9*100)=100,query('Final Attainment'!$H$7:$J$12, ""select H where I<=""&CEILING(R10/R9*100)&"" and J>=""&CEILING(R10/R9*100)&"""" ),query('Final Attainment'!$H$7:$J$12, ""select H where I<=""&CEILING(R10/R9*100)&"" and J>""&"&"CEILING(R10/R9*100)&"""" )))"),"") | S11: =IFERROR(__xludf.DUMMYFUNCTION("IF(S10=0,"""",if(CEILING(S10/S9*100)=100,query('Final Attainment'!$H$7:$J$12, ""select H where I<=""&CEILING(S10/S9*100)&"" and J>=""&CEILING(S10/S9*100)&"""" ),query('Final Attainment'!$H$7:$J$12, ""select H where I<=""&CEILING(S10/S9*100)&"" and J>""&"&"CEILING(S10/S9*100)&"""" )))"),"") | T11: =IFERROR(__xludf.DUMMYFUNCTION("IF(T10=0,"""",if(CEILING(T10/T9*100)=100,query('Final Attainment'!$H$7:$J$12, ""select H where I<=""&CEILING(T10/T9*100)&"" and J>=""&CEILING(T10/T9*100)&"""" ),query('Final Attainment'!$H$7:$J$12, ""select H where I<=""&CEILING(T10/T9*100)&"" and J>""&"&"CEILING(T10/T9*100)&"""" )))"),"") | U11: =IFERROR(__xludf.DUMMYFUNCTION("IF(U10=0,"""",if(CEILING(U10/U9*100)=100,query('Final Attainment'!$H$7:$J$12, ""select H where I<=""&CEILING(U10/U9*100)&"" and J>=""&CEILING(U10/U9*100)&"""" ),query('Final Attainment'!$H$7:$J$12, ""select H where I<=""&CEILING(U10/U9*100)&"" and J>""&"&"CEILING(U10/U9*100)&"""" )))"),3) -> 3 | V11: =IFERROR(__xludf.DUMMYFUNCTION("IF(V10=0,"""",if(CEILING(V10/V9*100)=100,query('Final Attainment'!$H$7:$J$12, ""select H where I<=""&CEILING(V10/V9*100)&"" and J>=""&CEILING(V10/V9*100)&"""" ),query('Final Attainment'!$H$7:$J$12, ""select H where I<=""&CEILING(V10/V9*100)&"" and J>""&"&"CEILING(V10/V9*100)&"""" )))"),"")
A12: Total No. of Attended Students: | E12: =U9 -> 66 | L12: Total No. of Students who need Remedial Class | R12: =R9-R10 -> 0 | S12: =S9-S10 -> 0 | T12: =T9-T10 -> 0 | U12: =U9-U10 -> 8 | V12: =V9-V10 -> 0
A14: S.No | B14: Reg.No. | C14: MARKS ALLOCATED | H14: MARKS OBTAINED | M14: CO ATTAINMENT % | R14: ATTAINMENT of COs | W14: IP2
C15: CO1 | D15: CO2 | E15: CO3 | F15: CO4 | G15: CO5 | H15: CO1 | I15: CO2 | J15: CO3 | K15: CO4 | L15: CO5 | M15: CO1 | N15: CO2 | O15: CO3 | P15: CO4 | Q15: CO5 | R15: CO1 | S15: CO2 | T15: CO3 | U15: CO4 | V15: CO5 | W15: Marks
A16: =Theory!A6 -> 1 | B16: =Theory!B6 -> 7376231EE102 | F16: 8 | K16: 7 | N16: =IF(D16="","",I16*100/D16) | O16: =IF(E16="","",J16*100/E16) | P16: =IF(F16="","",K16*100/F16) -> 87.5 | Q16: =IF(G16="","",L16*100/G16) | W16: =IP!E6 -> 7
A17: =Theory!A7 -> 2 | B17: =Theory!B7 -> 7376231EE103 | F17: 8 | K17: 7 | N17: =IF(D17="","",I17*100/D17) | O17: =IF(E17="","",J17*100/E17) | P17: =IF(F17="","",K17*100/F17) -> 87.5 | Q17: =IF(G17="","",L17*100/G17) | W17: =IP!E7 -> 7
A18: =Theory!A8 -> 3 | B18: =Theory!B8 -> 7376231EE104 | F18: 8 | K18: 4 | N18: =IF(D18="","",I18*100/D18) | O18: =IF(E18="","",J18*100/E18) | P18: =IF(F18="","",K18*100/F18) -> 50 | Q18: =IF(G18="","",L18*100/G18) | W18: =IP!E8 -> 4
A19: =Theory!A9 -> 4 | B19: =Theory!B9 -> 7376231EE105 | F19: 8 | K19: 7 | N19: =IF(D19="","",I19*100/D19) | O19: =IF(E19="","",J19*100/E19) | P19: =IF(F19="","",K19*100/F19) -> 87.5 | Q19: =IF(G19="","",L19*100/G19) | W19: =IP!E9 -> 7
A20: =Theory!A10 -> 5 | B20: =Theory!B10 -> 7376231EE106 | F20: 8 | K20: 7 | N20: =IF(D20="","",I20*100/D20) | O20: =IF(E20="","",J20*100/E20) | P20: =IF(F20="","",K20*100/F20) -> 87.5 | Q20: =IF(G20="","",L20*100/G20) | W20: =IP!E10 -> 7
A21: =Theory!A11 -> 6 | B21: =Theory!B11 -> 7376231EE107 | F21: 8 | K21: 8 | N21: =IF(D21="","",I21*100/D21) | O21: =IF(E21="","",J21*100/E21) | P21: =IF(F21="","",K21*100/F21) -> 100 | Q21: =IF(G21="","",L21*100/G21) | W21: =IP!E11 -> 8
A22: =Theory!A12 -> 7 | B22: =Theory!B12 -> 7376231EE108 | F22: 8 | K22: 8 | N22: =IF(D22="","",I22*100/D22) | O22: =IF(E22="","",J22*100/E22) | P22: =IF(F22="","",K22*100/F22) -> 100 | Q22: =IF(G22="","",L22*100/G22) | W22: =IP!E12 -> 8
A23: =Theory!A13 -> 8 | B23: =Theory!B13 -> 7376231EE109 | F23: 8 | K23: 7 | N23: =IF(D23="","",I23*100/D23) | O23: =IF(E23="","",J23*100/E23) | P23: =IF(F23="","",K23*100/F23) -> 87.5 | Q23: =IF(G23="","",L23*100/G23) | W23: =IP!E13 -> 7
A24: =Theory!A14 -> 9 | B24: =Theory!B14 -> 7376231EE110 | F24: 8 | K24: 8 | N24: =IF(D24="","",I24*100/D24) | O24: =IF(E24="","",J24*100/E24) | P24: =IF(F24="","",K24*100/F24) -> 100 | Q24: =IF(G24="","",L24*100/G24) | W24: =IP!E14 -> 8
A25: =Theory!A15 -> 10 | B25: =Theory!B15 -> 7376231EE111 | F25: 8 | K25: 1 | N25: =IF(D25="","",I25*100/D25) | O25: =IF(E25="","",J25*100/E25) | P25: =IF(F25="","",K25*100/F25) -> 12.5 | Q25: =IF(G25="","",L25*100/G25) | W25: =IP!E15 -> 1
A26: =Theory!A16 -> 11 | B26: =Theory!B16 -> 7376231EE112 | F26: 8 | K26: 6 | N26: =IF(D26="","",I26*100/D26) | O26: =IF(E26="","",J26*100/E26) | P26: =IF(F26="","",K26*100/F26) -> 75 | Q26: =IF(G26="","",L26*100/G26) | W26: =IP!E16 -> 6
A27: =Theory!A17 -> 12 | B27: =Theory!B17 -> 7376231EE113 | F27: 8 | K27: 7 | N27: =IF(D27="","",I27*100/D27) | O27: =IF(E27="","",J27*100/E27) | P27: =IF(F27="","",K27*100/F27) -> 87.5 | Q27: =IF(G27="","",L27*100/G27) | W27: =IP!E17 -> 7
... A81: =Theory!A71 -> 66 | B81: =Theory!B71 -> 7376241EE506 | F81: 8 | K81: 7 | N81: =IF(D81="","",I81*100/D81) | O81: =IF(E81="","",J81*100/E81) | P81: =IF(F81="","",K81*100/F81) -> 87.5 | Q81: =IF(G81="","",L81*100/G81) | W81: =IP!E71 -> 7

Sheet ESM
A1: ='Final Attainment'!A1:V1 -> 0
A2: ='Final Attainment'!A2:V2 -> 0
A4: Academic Year: | C4: ='Final Attainment'!C4 -> 2024-2025 EVEN | E4: Sem & Year: | G4: ='Final Attainment'!G4 -> IV & II | H4: Course Code & Title: | K4: ='Final Attainment'!K4:Q4 -> 22EE401 & POWER GENERATION, TRANSMISSION AND DISTRIBUTION | R4: Faculty: | S4: ='Final Attainment'!S4 -> Dr.SIVARAMAN P / EE1329
A6: End Semester Exam
A7: Scale | B7: ='Final Attainment'!X1 -> CO Attainment Level 0: <50% of students scoring less than the target marks CO Attainment Level 1: 50% of students scoring more than the target marks CO Attainment Level 2: 60% of students scoring more than the target marks CO Attainment Level 3: 70% of students scoring more than the target marks | L7: CO Attainment Summary
R8: CO1 | S8: CO2 | T8: CO3 | U8: CO4 | V8: CO5
L9: Total No. of Students | R9: =COUNTIF(H16:H361,">=0") -> 66 | S9: =COUNTIF(I16:I361,">=0") -> 66 | T9: =COUNTIF(J16:J361,">=0") -> 66 | U9: =COUNTIF(K16:K361,">=0") -> 66 | V9: =COUNTIF(L16:L361,">=0") -> 66
A10: Target CO%: | E10: ='Final Attainment'!E7 -> 58 | L10: Total No. of Students Achieved the Target CO% | R10: =COUNTIF(M16:M361,">="&$E$10) -> 53 | S10: =COUNTIF(N16:N361,">="&$E$10) -> 42 | T10: =COUNTIF(O16:O361,">="&$E$10) -> 50 | U10: =COUNTIF(P16:P361,">="&$E$10) -> 29 | V10: =COUNTIF(Q16:Q361,">="&$E$10) -> 47
A11: Total No. of Students: | E11: =COUNTA(B16:B361) -> 66 | L11: Attainment Level | R11: =IFERROR(__xludf.DUMMYFUNCTION("IF(R10=0,"""",if(CEILING(R10/R9*100)=100,query('Final Attainment'!$H$7:$J$12, ""select H where I<=""&CEILING(R10/R9*100)&"" and J>=""&CEILING(R10/R9*100)&"""" ),query('Final Attainment'!$H$7:$J$12, ""select H where I<=""&CEILING(R10/R9*100)&"" and J>""&"&"CEILING(R10/R9*100)&"""" )))"),3) -> 3 | S11: =IFERROR(__xludf.DUMMYFUNCTION("IF(S10=0,"""",if(CEILING(S10/S9*100)=100,query('Final Attainment'!$H$7:$J$12, ""select H where I<=""&CEILING(S10/S9*100)&"" and J>=""&CEILING(S10/S9*100)&"""" ),query('Final Attainment'!$H$7:$J$12, ""select H where I<=""&CEILING(S10/S9*100)&"" and J>""&"&"CEILING(S10/S9*100)&"""" )))"),2) -> 2 | T11: =IFERROR(__xludf.DUMMYFUNCTION("IF(T10=0,"""",if(CEILING(T10/T9*100)=100,query('Final Attainment'!$H$7:$J$12, ""select H where I<=""&CEILING(T10/T9*100)&"" and J>=""&CEILING(T10/T9*100)&"""" ),query('Final Attainment'!$H$7:$J$12, ""select H where I<=""&CEILING(T10/T9*100)&"" and J>""&"&"CEILING(T10/T9*100)&"""" )))"),3) -> 3 | U11: =IFERROR(__xludf.DUMMYFUNCTION("IF(U10=0,"""",if(CEILING(U10/U9*100)=100,query('Final Attainment'!$H$7:$J$12, ""select H where I<=""&CEILING(U10/U9*100)&"" and J>=""&CEILING(U10/U9*100)&"""" ),query('Final Attainment'!$H$7:$J$12, ""select H where I<=""&CEILING(U10/U9*100)&"" and J>""&"&"CEILING(U10/U9*100)&"""" )))"),0) -> 0 | V11: =IFERROR(__xludf.DUMMYFUNCTION("IF(V10=0,"""",if(CEILING(V10/V9*100)=100,query('Final Attainment'!$H$7:$J$12, ""select H where I<=""&CEILING(V10/V9*100)&"" and J>=""&CEILING(V10/V9*100)&"""" ),query('Final Attainment'!$H$7:$J$12, ""select H where I<=""&CEILING(V10/V9*100)&"" and J>""&"&"CEILING(V10/V9*100)&"""" )))"),3) -> 3
A12: Total No. of Attended Students: | E12: =R9 -> 66 | L12: Total No. of Students who need Remedial Class | R12: =R9-R10 -> 13 | S12: =S9-S10 -> 24 | T12: =T9-T10 -> 16 | U12: =U9-U10 -> 37 | V12: =V9-V10 -> 19
A14: S.No | B14: Reg.No. | C14: MARKS ALLOCATED | H14: MARKS OBTAINED | M14: CO ATTAINMENT % | R14: ATTAINMENT of COs
C15: CO1 | D15: CO2 | E15: CO3 | F15: CO4 | G15: CO5 | H15: CO1 | I15: CO2 | J15: CO3 | K15: CO4 | L15: CO5 | M15: CO1 | N15: CO2 | O15: CO3 | P15: CO4 | Q15: CO5 | R15: CO1 | S15: CO2 | T15: CO3 | U15: CO4 | V15: CO5
A16: =Theory!A6 -> 1 | B16: =Theory!B6 -> 7376231EE102 | C16: 20 | D16: 20 | E16: 20 | F16: 20 | G16: 20 | H16: 12 | I16: 14 | J16: 12 | K16: 15 | L16: 14 | M16: =IF(C16="","",H16*100/C16) -> 60 | N16: =IF(D16="","",I16*100/D16) -> 70 | O16: =IF(E16="","",J16*100/E16) -> 60 | P16: =IF(F16="","",K16*100/F16) -> 75 | Q16: =IF(G16="","",L16*100/G16) -> 70 | R16: =IF(M16>=$E$10,"1","0") -> 1 | S16: =IF(N16>=$E$10,"1","0") -> 1 | T16: =IF(O16>=$E$10,"1","0") -> 1 | U16: =IF(P16>=$E$10,"1","0") -> 1 | V16: =IF(Q16>=$E$10,"1","0") -> 1
A17: =Theory!A7 -> 2 | B17: =Theory!B7 -> 7376231EE103 | C17: 20 | D17: 20 | E17: 20 | F17: 20 | G17: 20 | H17: 13 | I17: 12 | J17: 12 | K17: 13 | L17: 11 | M17: =IF(C17="","",H17*100/C17) -> 65 | N17: =IF(D17="","",I17*100/D17) -> 60 | O17: =IF(E17="","",J17*100/E17) -> 60 | P17: =IF(F17="","",K17*100/F17) -> 65 | Q17: =IF(G17="","",L17*100/G17) -> 55 | R17: =IF(M17>=$E$10,"1","0") -> 1 | S17: =IF(N17>=$E$10,"1","0") -> 1 | T17: =IF(O17>=$E$10,"1","0") -> 1 | U17: =IF(P17>=$E$10,"1","0") -> 1 | V17: =IF(Q17>=$E$10,"1","0") -> 0
A18: =Theory!A8 -> 3 | B18: =Theory!B8 -> 7376231EE104 | C18: 20 | D18: 20 | E18: 20 | F18: 20 | G18: 20 | H18: 7 | I18: 1 | J18: 4 | K18: 8 | L18: 12 | M18: =IF(C18="","",H18*100/C18) -> 35 | N18: =IF(D18="","",I18*100/D18) -> 5 | O18: =IF(E18="","",J18*100/E18) -> 20 | P18: =IF(F18="","",K18*100/F18) -> 40 | Q18: =IF(G18="","",L18*100/G18) -> 60 | R18: =IF(M18>=$E$10,"1","0") -> 0 | S18: =IF(N18>=$E$10,"1","0") -> 0 | T18: =IF(O18>=$E$10,"1","0") -> 0 | U18: =IF(P18>=$E$10,"1","0") -> 0 | V18: =IF(Q18>=$E$10,"1","0") -> 1
A19: =Theory!A9 -> 4 | B19: =Theory!B9 -> 7376231EE105 | C19: 20 | D19: 20 | E19: 20 | F19: 20 | G19: 20 | H19: 19 | I19: 15 | J19: 14 | K19: 13 | L19: 9 | M19: =IF(C19="","",H19*100/C19) -> 95 | N19: =IF(D19="","",I19*100/D19) -> 75 | O19: =IF(E19="","",J19*100/E19) -> 70 | P19: =IF(F19="","",K19*100/F19) -> 65 | Q19: =IF(G19="","",L19*100/G19) -> 45 | R19: =IF(M19>=$E$10,"1","0") -> 1 | S19: =IF(N19>=$E$10,"1","0") -> 1 | T19: =IF(O19>=$E$10,"1","0") -> 1 | U19: =IF(P19>=$E$10,"1","0") -> 1 | V19: =IF(Q19>=$E$10,"1","0") -> 0
A20: =Theory!A10 -> 5 | B20: =Theory!B10 -> 7376231EE106 | C20: 20 | D20: 20 | E20: 20 | F20: 20 | G20: 20 | H20: 16 | I20: 12 | J20: 13 | K20: 10 | L20: 15 | M20: =IF(C20="","",H20*100/C20) -> 80 | N20: =IF(D20="","",I20*100/D20) -> 60 | O20: =IF(E20="","",J20*100/E20) -> 65 | P20: =IF(F20="","",K20*100/F20) -> 50 | Q20: =IF(G20="","",L20*100/G20) -> 75 | R20: =IF(M20>=$E$10,"1","0") -> 1 | S20: =IF(N20>=$E$10,"1","0") -> 1 | T20: =IF(O20>=$E$10,"1","0") -> 1 | U20: =IF(P20>=$E$10,"1","0") -> 0 | V20: =IF(Q20>=$E$10,"1","0") -> 1
A21: =Theory!A11 -> 6 | B21: =Theory!B11 -> 7376231EE107 | C21: 20 | D21: 20 | E21: 20 | F21: 20 | G21: 20 | H21: 11 | I21: 11 | J21: 13 | K21: 14 | L21: 16 | M21: =IF(C21="","",H21*100/C21) -> 55 | N21: =IF(D21="","",I21*100/D21) -> 55 | O21: =IF(E21="","",J21*100/E21) -> 65 | P21: =IF(F21="","",K21*100/F21) -> 70 | Q21: =IF(G21="","",L21*100/G21) -> 80 | R21: =IF(M21>=$E$10,"1","0") -> 0 | S21: =IF(N21>=$E$10,"1","0") -> 0 | T21: =IF(O21>=$E$10,"1","0") -> 1 | U21: =IF(P21>=$E$10,"1","0") -> 1 | V21: =IF(Q21>=$E$10,"1","0") -> 1
